Workbook

Sheet Summary
A1: NJ dispensary menu platforms
A2: Scan of the 331 locations on the NJ CRC dispensary map, Oct 2026. Counts are live formulas over the Stores tab.
A4: Menu platform | B4: Stores | C4: Share of all stores | D4: Share of identified
A5: Dutchie | B5: =COUNTIF(Stores!$G$2:$G$332,A5) -> 123 | C5: =B5/$B$26 -> 0.37160121 | D5: =B5/$B$22 -> 0.47674419
A6: Dispense | B6: =COUNTIF(Stores!$G$2:$G$332,A6) -> 55 | C6: =B6/$B$26 -> 0.16616314 | D6: =B6/$B$22 -> 0.21317829
A7: Sweed | B7: =COUNTIF(Stores!$G$2:$G$332,A7) -> 37 | C7: =B7/$B$26 -> 0.11178248 | D7: =B7/$B$22 -> 0.14341085
A8: Flowhub | B8: =COUNTIF(Stores!$G$2:$G$332,A8) -> 9 | C8: =B8/$B$26 -> 0.027190332 | D8: =B8/$B$22 -> 0.034883721
A9: Jane | B9: =COUNTIF(Stores!$G$2:$G$332,A9) -> 7 | C9: =B9/$B$26 -> 0.021148036 | D9: =B9/$B$22 -> 0.027131783
A10: Herb.co (Aggle) | B10: =COUNTIF(Stores!$G$2:$G$332,A10) -> 6 | C10: =B10/$B$26 -> 0.018126888 | D10: =B10/$B$22 -> 0.023255814
A11: Meadow | B11: =COUNTIF(Stores!$G$2:$G$332,A11) -> 4 | C11: =B11/$B$26 -> 0.012084592 | D11: =B11/$B$22 -> 0.015503876
A12: Blaze | B12: =COUNTIF(Stores!$G$2:$G$332,A12) -> 3 | C12: =B12/$B$26 -> 0.0090634441 | D12: =B12/$B$22 -> 0.011627907
A13: Shopify (custom storefront) | B13: =COUNTIF(Stores!$G$2:$G$332,A13) -> 3 | C13: =B13/$B$26 -> 0.0090634441 | D13: =B13/$B$22 -> 0.011627907
A14: Treez | B14: =COUNTIF(Stores!$G$2:$G$332,A14) -> 3 | C14: =B14/$B$26 -> 0.0090634441 | D14: =B14/$B$22 -> 0.011627907
A15: Proteus420 | B15: =COUNTIF(Stores!$G$2:$G$332,A15) -> 2 | C15: =B15/$B$26 -> 0.0060422961 | D15: =B15/$B$22 -> 0.007751938
A16: Carrot | B16: =COUNTIF(Stores!$G$2:$G$332,A16) -> 1 | C16: =B16/$B$26 -> 0.003021148 | D16: =B16/$B$22 -> 0.003875969
... A21: Leafly embed | B21: =COUNTIF(Stores!$G$2:$G$332,A21) -> 1 | C21: =B21/$B$26 -> 0.003021148 | D21: =B21/$B$22 -> 0.003875969
A22: Identified subtotal | B22: =SUM(B5:B21) -> 258 | C22: =B22/$B$26 -> 0.77945619 | D22: =B22/$B$22 -> 1
A23: Unidentified | B23: =COUNTIF(Stores!$G$2:$G$332,A23) -> 59 | C23: =B23/$B$26 -> 0.17824773
A24: Error | B24: =COUNTIF(Stores!$G$2:$G$332,A24) -> 1 | C24: =B24/$B$26 -> 0.003021148
A25: No website | B25: =COUNTIF(Stores!$G$2:$G$332,A25) -> 13 | C25: =B25/$B$26 -> 0.039274924
A26: Total stores | B26: =B22+SUM(B23:B25) -> 331 | C26: =B26/$B$26 -> 1
A28: Top 3 platforms (adapters to build first) | B28: =SUM(B5:B7) -> 215 | C28: =B28/$B$26 -> 0.64954683 | D28: =B28/$B$22 -> 0.83333333
A30: Why stores are unidentified
A31: Reason | B31: Stores
A32: Site failed to load in browser | B32: =COUNTIF(Stores!$J$2:$J$332,A32) -> 16
A33: Prismic-built site; no menu vendor request seen | B33: =COUNTIF(Stores!$J$2:$J$332,A33) -> 13
A34: No third-party menu vendor seen | B34: =COUNTIF(Stores!$J$2:$J$332,A34) -> 12
A35: Chain with first-party menu (unconfirmed) | B35: =COUNTIF(Stores!$J$2:$J$332,A35) -> 6
A36: Site blocked automated browser (HTTP 520) | B36: =COUNTIF(Stores!$J$2:$J$332,A36) -> 5
A37: Site blocked automated browser (HTTP 403) | B37: =COUNTIF(Stores!$J$2:$J$332,A37) -> 4
A38: Menu pages returned 404 | B38: =COUNTIF(Stores!$J$2:$J$332,A38) -> 2
A39: Site blocked automated browser (HTTP 409) | B39: =COUNTIF(Stores!$J$2:$J$332,A39) -> 1
A40: Site blocked automated browser (HTTP 525) | B40: =COUNTIF(Stores!$J$2:$J$332,A40) -> 1
A41: Total | B41: =SUM(B32:B40) -> 60

Sheet Stores
A1: Store | B1: Town | C1: ZIP | D1: State map tags | E1: Website | F1: Menu URL scanned | G1: Menu platform | H1: Confidence | I1: Evidence | J1: Why unidentified | K1: Note | L1: API paths seen
A2: Flowerbomb Dispensary | B2: Irvington | C2: 07111 | D2: Recreational cannabis | E2: https://flowerbombdispensarynj.com/ | F2: https://flowerbombdispensarynj.com/shop/ | G2: Blaze | H2: high | I2: html:blaze.me; request:ecom-api.blaze.me; request:growth-api.blaze.me | L2: api.mapbox.com/geocoding/v5/mapbox.places/1108%20Clinton%20Ave,%20Irvington,%20NJ%2007111.json;cdn.acsbapp.com/cache/app/wildcards.json;cdn.acsbapp.com/config/flowerbombdispensarynj.com/config.json;ecom-api.blaze.me/api/v1/products/recommendations/sponsored-user-top-picks/
A3: MMD NJ | B3: Jersey City | C3: 07306 | D3: Recreational cannabis|Offers delivery | E3: https://mmdshops.com/location/jersey-city/ | F3: https://mmdshops.com/locations/jersey-city/ | G3: Blaze | H3: high | I3: html:blaze.me; iframe:chat.blaze.me; request:chat.blaze.me; request:ecom-api.blaze.me | L3: api.mapbox.com/geocoding/v5/mapbox.places/655%20Newark%20Avenue,%20Jersey%20City,%20NJ%2007306.json;cdn.acsbapp.com/config/mmdshops.com/config.json;col.surfside.io/event/track;collector-azsx401.dmp.cnna.io/analytics/track
A4: Roots Dispensary | B4: Willingboro | C4: 08046 | D4: Expanded ATC (Both Med & Rec)|Medicinal cannabis|Recreational cannabis | E4: http://rootsnj.com | F4: https://rootsnj.com/recreational/brands/ | G4: Blaze | H4: high | I4: html:blaze.me; request:ecom-api.blaze.me; request:growth-api.blaze.me | L4: api.mapbox.com/geocoding/v5/mapbox.places/4402%20US-130,%20Willingboro,%20NJ%2008046.json;cdn.acsbapp.com/config/rootsnj.com/config.json;ecom-api.blaze.me/api/v1/products/;ecom-api.blaze.me/api/v1/products/recommendations/sponsored-user-top-picks/
A5: The Cannabis Place | B5: Jersey City | C5: 07305 | D5: Recreational cannabis|Offers delivery | E5: https://thecannabisplace.org/ | F5: https://thecannabisplace.org/store?locId=2 | G5: Carrot | H5: high | I5: request:api.nevada.getcarrot.io; request:nevada-store-core.getcarrot.io; request:openreplay.getcarrot.io | L5: api.nevada.getcarrot.io/api/v1/customer/me/cart;api.nevada.getcarrot.io/api/v1/store/category;api.nevada.getcarrot.io/api/v1/store/flags;api.nevada.getcarrot.io/api/v1/store/locations
A6: Green Wellness Haven | B6: Pleasantville | C6: 08232 | D6: Microbusiness|Recreational cannabis | E6: http://www.learngreenhaven.com | F6: https://shop.greenhavennj.com/ | G6: Cova | H6: medium | I6: html:covasoft | L6: a.visitor-speed.com/x/y;api.leadpages.io/analytics/v1/events/capture;idx.liadm.com/idex/did-0014/any;js.monitor.azure.com/scripts/b/ai.config.1.cfg.json
A7: Salt Air Botanicals | B7: Atlantic City | C7: 08401 | D7: Microbusiness|Recreational cannabis | E7: https://www.saltairbotanicals.com/ | F7: https://saltairbotanicals.com/menu | G7: Dispense | H7: high | I7: html:dispenseapp.com; request:api.dispenseapp.com; request:dispense-images.imgix.net; also:POSaBIT | L7: api.dispenseapp.com/user/me;api.dispenseapp.com/v1/organizations/0d4970ebc697aaf5/banners;api.dispenseapp.com/v1/users/c6e9e38d8476b8c2/loyalty-profile;api.dispenseapp.com/v1/venues/5f94eb97f7377a96/product-categories/df281e28a06804f7/products
A8: A-Z Supply | B8: Bloomfield | C8: 07003 | D8: Recreational cannabis | E8: https://azsupplynj.com/ | F8: https://azsupplynj.com/order/categories/rare-deals-limited-time-only | G8: Dispense | H8: high | I8: html:dispenseapp.com; iframe:menus.dispenseapp.com; request:api.dispenseapp.com; request:dispense-images.imgix.net | L8: api.dispenseapp.com/user/me;api.dispenseapp.com/v1/organizations/578734f8118f28f9/banners;api.dispenseapp.com/v1/users/cdc413268c6a946c/loyalty-profile;api.dispenseapp.com/v1/venues/c88aefe3940805df/product-categories/71d1acf8cba229a8/products
A9: Blue Oak NJ 1 | B9: Bloomfield | C9: 07003 | D9: Recreational cannabis|Offers delivery|Microbusiness | E9: http://blueoaknj.com | F9: https://blueoaknj.com/shop/offers | G9: Dispense | H9: high | I9: html:dispenseapp.com; request:api.dispenseapp.com; request:dispense-images.imgix.net; also:POSaBIT | L9: api.dispenseapp.com/user/me;api.dispenseapp.com/v1/organizations/a02b1797d236c28e/banners;api.dispenseapp.com/v1/users/ceffeb4387365865/loyalty-profile;api.dispenseapp.com/v1/venues/7450756b1ee88bad/product-categories/f25da7554b980f55/products
A10: Indigo | B10: Brooklawn | C10: 08030 | D10: Recreational cannabis|Offers delivery | E10: https://www.indigodispensary.com/ | F10: https://www.indigodispensary.com/shop/categories/flower | G10: Dispense | H10: high | I10: html:dispenseapp.com; request:api.dispenseapp.com; request:dispense-images.imgix.net; request:js.dispenseapp.com | L10: api.dispenseapp.com/user/me;api.dispenseapp.com/v1/organizations/9b37790780473ec5/banners;api.dispenseapp.com/v1/users/b881c5d80d2cd8c4/loyalty-profile;api.dispenseapp.com/v1/venues/041444e70b831110/product-categories/4990fabc69688bb8/products
A11: Taste of Earth | B11: Buena | C11: 08310 | D11: Microbusiness|Recreational cannabis | E11: https://tasteofearth.co/ | F11: https://tasteofearth.co/shop | G11: Dispense | H11: high | I11: html:dispenseapp.com; request:api.dispenseapp.com; request:dispense-images.imgix.net | L11: api.dispenseapp.com/user/me;api.dispenseapp.com/v1/organizations/0f38e2d8cb267b4c/banners;api.dispenseapp.com/v1/users/de031079a2f3007d/loyalty-profile;api.dispenseapp.com/v1/venues/95ec4d149d67b404/product-categories/c6f3c0bf4f58b982/products
A12: Shore House Canna | B12: Cape May | C12: 08204 | D12: Recreational cannabis|Offers delivery | E12: https://shorehousecanna.com/ | F12: https://www.shorehousecanna.com/menu/offers | G12: Dispense | H12: high | I12: html:dispenseapp.com; iframe:menus.dispenseapp.com; request:api.dispenseapp.com; request:dispense-images.imgix.net | L12: api.dispenseapp.com/user/me;api.dispenseapp.com/v1/organizations/55cb13cd55dc83ba/banners;api.dispenseapp.com/v1/users/e2de42471aba6bcf/loyalty-profile;api.dispenseapp.com/v1/venues/89d4331affeab63c/product-categories/16b292bcdb01347a/products
A13: NJ LEAF Aberdeen | B13: Cliffwood | C13: 07721 | E13: https://njleaf.com/ | F13: https://njleaf.com/products/flower/ | G13: Dispense | H13: medium | I13: html:dispenseapp.com | L13: njleaf.com/cdn-cgi/rum
A14: NJ Leaf Aberdeen | B14: Cliffwood | C14: 07721 | D14: Medicinal cannabis|Recreational cannabis|Expanded ATC (Both Med & Rec) | E14: https://njleaf.com/ | F14: https://njleaf.com/products/flower/ | G14: Dispense | H14: medium | I14: html:dispenseapp.com; reused:same-url | L14: njleaf.com/cdn-cgi/rum
A15: Med Leaf | B15: Egg Harbor City | C15: 08215 | D15: Recreational cannabis | E15: https://www.medleafdispensary.com/ | F15: https://menus.dispenseapp.com/9e34aad030c6f68f/menu/offers | G15: Dispense | H15: high | I15: html:dispenseapp.com; request:api.dispenseapp.com; request:dispense-images.imgix.net; request:menus.dispenseapp.com | L15: col.surfside.io/event/track;engage.wixapps.net/_api/chat-web/v1/chatrooms-for-list-view;engage.wixapps.net/_api/chat-web/v1/display-data/current-user;engage.wixapps.net/_api/chat-web/v1/real-time-tokens
A16: City Leaves | B16: Egg Harbor Township | C16: 08234 | D16: Recreational cannabis | E16: http://cityleaves.com | F16: https://cityleaves.com/shop | G16: Dispense | H16: high | I16: html:dispense-images.imgix; html:dispenseapp.com; request:api.dispenseapp.com; request:dispense-images.imgix.net | L16: api.dispenseapp.com/user/me;api.dispenseapp.com/v1/organizations/06f4c19c09247cd3/banners;api.dispenseapp.com/v1/users/159082396d65d816/loyalty-profile;api.dispenseapp.com/v1/venues/94b97cba76dcbc82/product-categories/11abdf4b255a60c6/products
A17: Conservatory Cannabis Company | B17: Egg Harbor Township | C17: 08234 | D17: Recreational cannabis | E17: http://www.conservatorycannabis.com/ | F17: https://shop.conservatorycannabis.com/shop | G17: Dispense | H17: high | I17: html:dispense-images.imgix; html:dispenseapp.com; request:api.dispenseapp.com; request:dispense-images.imgix.net | L17: api.dispenseapp.com/user/me;api.dispenseapp.com/v1/organizations/c78b003ea247551e/banners;api.dispenseapp.com/v1/users/26c2118cdd80ee01/loyalty-profile;api.dispenseapp.com/v1/venues/482264628c7deb3e/product-categories/1f26b8beb1f4abe0/products
A18: Plantopia | B18: Englishtown | C18: 07726 | D18: Microbusiness|Recreational cannabis | E18: https://plantopiadispensaries.com/?utm_source=google_business&utm_medium=organic&utm_campaign=GBP_englishtown | F18: https://plantopiadispensaries.com/menu/ | G18: Dispense | H18: high | I18: html:dispenseapp.com; request:api.dispenseapp.com; request:dispense-images.imgix.net; also:POSaBIT | L18: api.dispenseapp.com/user/me;api.dispenseapp.com/v1/organizations/63111213d645e6a1/banners;api.dispenseapp.com/v1/users/fc83115a709c4eea/loyalty-profile;api.dispenseapp.com/v1/venues/d73719cc285d62b5/product-categories/9cea83dbe1109fd4/products
A19: Ruuted | B19: Englishtown | C19: 07726 | D19: Recreational cannabis|Offers delivery | E19: http://ruuteddispensary.com/ | F19: https://ruuteddispensary.com/dispensary-delivery/ | G19: Dispense | H19: high | I19: html:dispenseapp.com; request:api.dispenseapp.com; request:dispense-images.imgix.net; also:POSaBIT | L19: api.dispenseapp.com/user/me;api.dispenseapp.com/v1/organizations/2fd6f35442196ce4/banners;api.dispenseapp.com/v1/users/f1c5d7da5d76e769/loyalty-profile;api.dispenseapp.com/v1/venues/257c8e61fe900044/product-filters
A20: NJ Leaf Freehold | B20: Freehold | C20: 07728 | D20: Expanded ATC (Both Med & Rec)|Medicinal cannabis|Recreational cannabis | E20: https://njleaf.com/ | F20: https://njleaf.com/products/flower/ | G20: Dispense | H20: medium | I20: html:dispenseapp.com; reused:same-url | L20: njleaf.com/cdn-cgi/rum
A21: High Street Dispensary | B21: Hackettstown | C21: 07840 | D21: Recreational cannabis|Offers delivery | E21: https://www.njhighstreet.com/ | F21: https://njhighstreet.com/menu | G21: Dispense | H21: high | I21: html:dispense-images.imgix; html:dispenseapp.com; request:api.dispenseapp.com; request:dispense-images.imgix.net | L21: api.dispenseapp.com/user/me;api.dispenseapp.com/v1/organizations/76b7ad1bbe2c7d8d/banners;api.dispenseapp.com/v1/users/14a1cf13b0587266/loyalty-profile;api.dispenseapp.com/v1/venues/5d76cf0363f89fe7/product-filters
A22: Molly Ann Farms | B22: Haledon | C22: 07508 | D22: Recreational cannabis | E22: https://www.mollyannfarms.com/ | F22: https://www.mollyannfarms.com/shop-now | G22: Dispense | H22: high | I22: html:dispense-images.imgix; html:dispenseapp.com; request:api.dispenseapp.com; request:dispense-images.imgix.net | L22: api.dispenseapp.com/user/me;api.dispenseapp.com/v1/organizations/94a363e71d12a909/banners;api.dispenseapp.com/v1/users/e6a40bf5ae63802a/loyalty-profile;api.dispenseapp.com/v1/venues/cfe5f6a8f1d10470/product-categories/abc853006171b228/products
A23: 4Twenty Somewhere | B23: Hewitt | C23: 07421 | D23: Recreational cannabis|Offers delivery | E23: https://4twentysomewhere.com/ | F23: https://4twentysomewhere.com/shop/ | G23: Dispense | H23: high | I23: html:dispenseapp.com; request:api.dispenseapp.com; request:dispense-images.imgix.net; also:POSaBIT | L23: api.dispenseapp.com/user/me;api.dispenseapp.com/v1/organizations/2f1f1c61acf3748d/banners;api.dispenseapp.com/v1/users/06dbf67c592885e2/loyalty-profile;api.dispenseapp.com/v1/venues/680b325c2357c0ab/product-categories/1809026f5ac5f377/products
A24: Anja Life | B24: Highland Park | C24: 08904 | D24: Recreational cannabis|Offers delivery | E24: https://www.getanja.com/ | F24: https://www.getanja.com/shop/none/12pc-cigarette-pack-holder-kingsize | G24: Dispense | H24: high | I24: html:dispenseapp.com; request:api.dispenseapp.com; request:dispense-images.imgix.net; request:stores.dispenseapp.com | L24: api.dispenseapp.com/user/me;api.dispenseapp.com/v1/organizations/f7f4fccd2ec1634a/banners;api.dispenseapp.com/v1/users/e3dff4d7c61c0742/loyalty-profile;api.dispenseapp.com/v1/venues/75b89af98283d723/product-categories/a17d852d68b324c1/products
A25: Jersey Leaf | B25: Jersey City | C25: 07304 | D25: Microbusiness|Recreational cannabis | E25: https://jerseyleaf.net/ | F25: https://jerseyleaf.net/menu | G25: Dispense | H25: high | I25: html:dispenseapp.com; request:api.dispenseapp.com; request:dispense-images.imgix.net; request:js.dispenseapp.com | L25: api.dispenseapp.com/user/me;api.dispenseapp.com/v1/organizations/1c7af7a55b093996/banners;api.dispenseapp.com/v1/users/abdc9679e5a9f0be/loyalty-profile;api.dispenseapp.com/v1/venues/27ac0bd81be82e2b/product-categories/c4a76a4e4fc10eb3/products
... A44: Jersey Meds | B44: Pennington | C44: 08534 | D44: Recreational cannabis|Offers delivery | E44: http://jerseymeds.com | F44: https://jerseymeds.com/shop/categories/edibles | G44: Dispense | H44: high | I44: html:dispenseapp.com; request:api.dispenseapp.com; request:dispense-images.imgix.net; also:POSaBIT | L44: api.dispenseapp.com/user/me;api.dispenseapp.com/v1/users/6f7fa176b4babab9/loyalty-profile;api.dispenseapp.com/v1/venues/2c0db436f9815b7c/product-categories/1738a7fc3458092b/products;api.dispenseapp.com/v1/venues/2c0db436f9815b7c/product-categories/89dd099e8b08050f/products
A45: CannaVerde Dispensary | B45: Plainfield | C45: 07060 | E45: https://cannaverdenj.com/shop | F45: https://cannaverdenj.com/shop/cart | G45: Dispense | H45: high | I45: html:dispenseapp.com; request:api.dispenseapp.com; request:dispense-images.imgix.net | L45: api.dispenseapp.com/user/me;api.dispenseapp.com/v1/organizations/b884475444b21950/banners;api.dispenseapp.com/v1/users/b1c0df0f5ca65ff0/loyalty-profile;api.dispenseapp.com/v1/venues/c873f0d3ace99f68/product-categories/6244041771ac5453/products
A46: Island Vibez | B46: Plainfield | C46: 07060 | D46: Microbusiness|Recreational cannabis | E46: http://islandvibezdispensary.com | F46: https://menus.dispenseapp.com/86fc4f1d31772362/menu/categories/flower | G46: Dispense | H46: high | I46: html:dispenseapp.com; iframe:menus.dispenseapp.com; request:api.dispenseapp.com; request:dispense-images.imgix.net | L46: api.dispenseapp.com/user/me;api.dispenseapp.com/v1/organizations/bbfa1a36700f6519/banners;api.dispenseapp.com/v1/users/a303f9cfed1e61df/loyalty-profile;api.dispenseapp.com/v1/venues/86fc4f1d31772362/product-categories/247f28b30bdc55f6/products
A47: Queen City Remedies | B47: Plainfield | C47: 07062 | D47: Recreational cannabis | E47: https://queencitynj.com/ | F47: https://queencitynj.com/kiosk-ordering/ | G47: Dispense | H47: high | I47: html:dispenseapp.com; request:api.dispenseapp.com; request:dispense-images.imgix.net; also:POSaBIT | L47: api.dispenseapp.com/user/me;api.dispenseapp.com/v1/organizations/6f1e5bb605be1d29/banners;api.dispenseapp.com/v1/users/33524442cb5555c0/loyalty-profile;api.dispenseapp.com/v1/venues/c7a90aef64ff484d/product-categories/d87b6c7c05f00a73/products
A48: The Frosted Nug at Red Bank | B48: Red Bank | C48: 07701 | D48: Recreational cannabis | E48: https://frostednug.com/ | F48: https://frostednug.com/menu/carneys-point/offers | G48: Dispense | H48: high | I48: html:dispenseapp.com; request:api.dispenseapp.com; request:dispense-images.imgix.net; request:js.dispenseapp.com | L48: api.dispenseapp.com/user/me;api.dispenseapp.com/v1/venues/2024883014413667/product-filters;api.dispenseapp.com/v1/venues/2024883014413667/product-offers;api.dispenseapp.com/v1/venues/2024883014413667/product-offers/072f089295ceb07e/products
A49: G2 Dispensary | B49: Rockaway | C49: 07866 | D49: Recreational cannabis | E49: http://G2dispensary.com | F49: https://www.g2dispensary.com/menu/cart | G49: Dispense | H49: high | I49: html:dispenseapp.com; request:api.dispenseapp.com; request:dispense-images.imgix.net | L49: api.dispenseapp.com/user/me;api.dispenseapp.com/v1/organizations/212d84a4526e9399/banners;api.dispenseapp.com/v1/users/46826b8c2d0550a3/loyalty-profile;api.dispenseapp.com/v1/venues/245c8f238f29c512/product-categories/87e59bbe167aad5b/products
A50: A21 Wellness | B50: Scotch Plains | C50: 07076 | D50: Recreational cannabis|Offers delivery|Microbusiness | E50: https://a21dispensary.com/ | F50: https://a21dispensary.com/cannabis-delivery/ | G50: Dispense | H50: high | I50: html:dispenseapp.com; request:api.dispenseapp.com; request:dispense-images.imgix.net | L50: a21dispensary.com/cdn-cgi/rum;api.dispenseapp.com/user/me;api.dispenseapp.com/v1/organizations/3954d316be694892/banners;api.dispenseapp.com/v1/users/51f67028f1f4ae94/loyalty-profile
A51: B Caf Dispensary | B51: Scotch Plains | C51: 07076 | D51: Recreational cannabis | E51: https://www.bcafdispensary.com/ | F51: https://www.bcafdispensary.com/dispensary-near-berkeley-heights-nj/ | G51: Dispense | H51: high | I51: html:dispenseapp.com; request:api.dispenseapp.com; request:dispense-images.imgix.net; also:POSaBIT | L51: api.dispenseapp.com/user/me;api.dispenseapp.com/v1/organizations/f674e142a92d78db/banners;api.dispenseapp.com/v1/users/40d62cae9b7b826a/loyalty-profile;api.dispenseapp.com/v1/venues/de37ee984a8de298/product-categories/665af1814594b7ae/products
A52: Happy Leaf | B52: Somerdale | C52: 08083 | D52: Microbusiness|Recreational cannabis | E52: https://happyleafdispensarynj.com/ | F52: https://happyleafdispensarynj.com/drive-thru | G52: Dispense | H52: medium | I52: html:dispenseapp.com | L52: happyleafdispensarynj.com/;happyleafdispensarynj.com/contact;happyleafdispensarynj.com/deals;happyleafdispensarynj.com/drive-thru
A53: SilverLeaf Wellness | B53: Somerset | C53: 08873 | D53: Expanded ATC (Both Med & Rec)|Medicinal cannabis|Recreational cannabis | E53: https://silverleafnj.com/ | F53: https://silverleafnj.com/menu/rec | G53: Dispense | H53: high | I53: html:dispenseapp.com; request:api.dispenseapp.com; request:dispense-images.imgix.net; also:POSaBIT | L53: ai.virtualbudz.com/admin/business/silverleaf_sil/popup-icon;ai.virtualbudz.com/admin/business/silverleaf_sil/popup-message;ai.virtualbudz.com/admin/business/silverleaf_sil/quick-responses;ai.virtualbudz.com/admin/business/silverleaf_sil/season_status
A54: New Era Dispensary | B54: South Bound Brook | C54: 08880 | D54: Recreational cannabis | E54: https://neweradispensary.com/ | F54: https://neweradispensary.com/ | G54: Dispense | H54: high | I54: html:dispenseapp.com; request:api.dispenseapp.com; request:dispense-images.imgix.net; also:POSaBIT | L54: api.dispenseapp.com/user/me;api.dispenseapp.com/v1/organizations/890f2911f7edec76/banners;api.dispenseapp.com/v1/users/96bc8dfc61fe88bd/loyalty-profile;api.dispenseapp.com/v1/venues/82fdd505d4f2d67a/product-categories/12cf734a5f4cd1ad/products
A55: RushBudz Dispensary | B55: South Bound Brook | C55: 08880 | D55: Recreational cannabis|Offers delivery | E55: https://www.rushbudz.com/new-jersey | F55: https://rushbudz.com/menu/ | G55: Dispense | H55: high | I55: html:dispenseapp.com; request:api.dispenseapp.com; request:dispense-images.imgix.net; also:POSaBIT | L55: api.dispenseapp.com/user/me;api.dispenseapp.com/v1/organizations/75b3285520c40136/banners;api.dispenseapp.com/v1/users/671a2bde88a46caa/loyalty-profile;api.dispenseapp.com/v1/venues/4870989abbd32896/product-categories/8d94b9c312fa68d1/products
A56: Cannabis Clubhouse | B56: Sussex | C56: 07461 | D56: Recreational cannabis|Offers delivery | E56: https://www.cannabisclubhousenj.com/ | F56: https://menus.dispenseapp.com/1c1e4e3311e11e41/menu | G56: Dispense | H56: high | I56: html:dispenseapp.com; request:api.dispenseapp.com; request:dispense-images.imgix.net; request:menus.dispenseapp.com | L56: api.dispenseapp.com/user/me;api.dispenseapp.com/v1/organizations/235f62b898a13e82/banners;api.dispenseapp.com/v1/users/67fe2f4c47c32e09/loyalty-profile;api.dispenseapp.com/v1/venues/1c1e4e3311e11e41/product-categories/d8780f9281654390/products
A57: Vigor Dispensary - Tinton Falls | B57: Tinton Falls | C57: 07753 | D57: Recreational cannabis | E57: https://vigordispensary.com/ | F57: https://vigordispensary.com/shop/vigor-select/ | G57: Dispense | H57: high | I57: html:dispenseapp.com; request:js.dispenseapp.com; also:Sweed; reused:same-url | L57: vigordispensary.com/cdn-cgi/challenge-platform/h/b/fo/725451836:1792768209:ivTpDb-zKS-sVYQWGUnyLJAvlHGzocEMC4zKyc5cWIM/a;vigordispensary.com/cdn-cgi/challenge-platform/h/b/jsd/oneshot/d2d3316b729e/0.8382033251339321:1792768220:2Uqp6YEyPN8Gte
... A111: BLKBRN Cannabis Dispensary | B111: Highland Park | C111: 08904 | D111: Recreational cannabis | E111: https://www.blkbrndispensary.com/ | F111: https://dutchie.com/embedded-menu/66cf5c3ac9fd392b86e202e9 | G111: Dutchie | H111: high | I111: html:dutchie.com; html:embedded-menu; iframe:dutchie.com; request:api.dutchie.com | L111: dutchie.com/api-3/graphql;dutchie.com/graphql;dutchie.com/telemetry;fides.dutchie.com/api/v1/privacy-experience
...

Sheet Notes
A1: How this was built
A2: Store list | B2: The 331 pins on the NJ Cannabis Regulatory Commission dispensary map (retail, microbusiness, medical/ATC). Includes licensed locations that may not yet be open.
A3: Detection | B3: Headless Chromium visited each store website and its menu pages. A platform is named from hosts the page requested, iframes, and footer credits (high = request or iframe seen; medium = page text or hostname inference).
A4: Inferred vendors | B4: Herb.co (Aggle), Hytiva, Proteus420, Carrot, Joint Commerce and Hashly were named from hostnames only; not confirmed on the vendors' own sites.
A5: Brotherly Bud | B5: Footer credits LeafBridge (site builder), but menu requests go to Dutchie, so it is listed as Dutchie.
A6: NAR Cannabis | B6: Marked Shopify from a manual check: menu is on shopnarcannabis.com (Shopify); narcannabis.com is a Framer brochure site.
A7: Unidentified | B7: Not "no menu": many are blocked, failed to load, or run first-party menus. Curaleaf, RISE, Ayr and The Cannabist sites could not be read by automated tools.
A8: Coverage caveat | B8: A partial cross-check against CRC license records (businesses A-N only) matched about 86% of licensed locations to a map pin; the O-Z half was not checked.
A9: Refreshing | B9: Re-run crawl.py detect to refresh; menu platforms change when stores switch vendors.
